Traceback (most recent call last):
  File "/home/codespace/.local/lib/python3.12/site-packages/jupyter_core/utils/__init__.py", line 154, in wrapped
    asyncio.get_running_loop()
RuntimeError: no running event loop

During handling of the above exception, another exception occurred:

Traceback (most recent call last):
  File "/usr/local/python/3.12.1/lib/python3.12/site-packages/jupyter_cache/executors/utils.py", line 58, in single_nb_execution
    executenb(
  File "/home/codespace/.local/lib/python3.12/site-packages/nbclient/client.py", line 1319, in execute
    return NotebookClient(nb=nb, resources=resources, km=km, **kwargs).execute()
           ^^^^^^^^^^^^^^^^^^^^^^^^^^^^^^^^^^^^^^^^^^^^^^^^^^^^^^^^^^^^^^^^^^^^^
  File "/home/codespace/.local/lib/python3.12/site-packages/jupyter_core/utils/__init__.py", line 158, in wrapped
    return loop.run_until_complete(inner)
           ^^^^^^^^^^^^^^^^^^^^^^^^^^^^^^
  File "/usr/local/python/3.12.1/lib/python3.12/asyncio/base_events.py", line 684, in run_until_complete
    return future.result()
           ^^^^^^^^^^^^^^^
  File "/home/codespace/.local/lib/python3.12/site-packages/nbclient/client.py", line 709, in async_execute
    await self.async_execute_cell(
  File "/home/codespace/.local/lib/python3.12/site-packages/nbclient/client.py", line 1062, in async_execute_cell
    await self._check_raise_for_error(cell, cell_index, exec_reply)
  File "/home/codespace/.local/lib/python3.12/site-packages/nbclient/client.py", line 918, in _check_raise_for_error
    raise CellExecutionError.from_cell_and_msg(cell, exec_reply_content)
nbclient.exceptions.CellExecutionError: An error occurred while executing the following cell:
------------------
import openeo

connection = openeo.connect("openeo.dataspace.copernicus.eu").authenticate_oidc()

aoi = {
    "type": "Polygon",
        "coordinates": [
        [
            [
                112.76,
                -7.021
            ],
            [
                112.74,
                -7.021
            ],
            [
                112.74,
                -7.035
            ],
            [
                112.76,
                -7.035
            ],
            [
                112.76,
                -7.021
            ]
        ]
    ],
    "type": "Polygon"
}

s5p_no2 = connection.load_collection(
    "SENTINEL_5P_L2",
    temporal_extent=["2023-10-15", "2025-10-19"],
    spatial_extent={
        "west": 112.60,
        "south": -7.10,
        "east": 112.90,
        "north": -6.90
    },
    bands=["NO2"]
)

# 4. Hitung rata-rata harian
s5p_no2_daily = s5p_no2.aggregate_temporal_period(
    period="day",
    reducer="mean"
)

# 5. Hitung rata-rata spasial berdasarkan AOI
s5p_no2_aoi = s5p_no2_daily.aggregate_spatial(
    geometries=aoi,
    reducer="mean"
)

job = s5p_no2.execute_batch(title="NO2 in bangkalan", outputfile="NO2_in_bangkalan.nc")
------------------


[31m---------------------------------------------------------------------------[39m
[31mModuleNotFoundError[39m                       Traceback (most recent call last)
[36mCell[39m[36m [39m[32mIn[1][39m[32m, line 1[39m
[32m----> [39m[32m1[39m [38;5;28;01mimport[39;00m[38;5;250m [39m[34;01mopeneo[39;00m
[32m      3[39m connection = openeo.connect([33m"[39m[33mopeneo.dataspace.copernicus.eu[39m[33m"[39m).authenticate_oidc()
[32m      5[39m aoi = {
[32m      6[39m     [33m"[39m[33mtype[39m[33m"[39m: [33m"[39m[33mPolygon[39m[33m"[39m,
[32m      7[39m         [33m"[39m[33mcoordinates[39m[33m"[39m: [
[32m   (...)[39m[32m     31[39m     [33m"[39m[33mtype[39m[33m"[39m: [33m"[39m[33mPolygon[39m[33m"[39m
[32m     32[39m }

[31mModuleNotFoundError[39m: No module named 'openeo'

